Workbook
Name СписокПредметов_511: OFFSET(Предметы!$A$2,0,0,COUNTA(Предметы!$A:$A)-1,1)

Sheet 5 классы
A1: РАСПИСАНИЕ УРОКОВ — 5 КЛАССЫ
A2: Кл. руководитель | D2: Илюшина Н.Н. (231) | E2: Шавалиева Е.В. (343) | F2: Кижеватова Т.В. (115) | G2: Степанова Л.Г. (муз.)
A3: День | B3: № | C3: Время | D3: 5 «А» | E3: 5 «Б» | F3: 5 «В» | G3: 5 «Г»
A4: ПОНЕДЕЛЬНИК | B4: 1. | C4: =Звонки!B2 -> 8.35-9.15 | D4: Литература | E4: География | F4: История | G4: Математика
B5: 2. | C5: =Звонки!B3 -> 9.30-10.10 | D5: Русский язык | E5: Математика | F5: Математика | G5: История
B6: 3. | C6: =Звонки!B4 -> 10.25-11.05 | D6: Естествознание | E6: Русский язык | F6: Русский язык | G6: Русский язык
B7: 4. | C7: =Звонки!B5 -> 11.25-12.05 | D7: Математика | E7: История | F7: Литература | G7: Технология
B8: 5. | C8: =Звонки!B6 -> 12.25-13.05 | D8: История | E8: Иностранный язык | F8: Иностранный язык | G8: Технология
B9: 6. | C9: =Звонки!B7 -> 13.20-14.00 | D9: ПОУ ИНОСТРАННЫЙ | E9: Литература | F9: География | G9: Литература
A10: ВТОРНИК | B10: 1. | C10: =Звонки!C2 -> 8.00-8.40 | D10: Физическая культура | E10: Математика | F10: Математика | G10: Иностранный язык
B11: 2. | C11: =Звонки!C3 -> 8.55-9.35 | D11: Биология | E11: Математика | F11: Иностранный язык | G11: Физическая культура
B12: 3. | C12: =Звонки!C4 -> 9.50-10.30 | D12: Русский язык | E12: Биология | F12: Технология | G12: Математика
B13: 4. | C13: =Звонки!C5 -> 10.50-11.30 | D13: Математика | E13: История | F13: Технология | G13: География
B14: 5. | C14: =Звонки!C6 -> 11.50-12.30 | D14: История | E14: Русский язык | F14: Русский язык | G14: Русский язык
B15: 6. | C15: =Звонки!C7 -> 12.45-13.25 | D15: География | E15: Физическая культура | F15: Биология | G15: ПОУ РУССКИЙ ЯЗЫК
B16: 7. | C16: =Звонки!C8 -> 13.35-14.15 | D16: ПОУ РУССКИЙ ЯЗЫК
A17: СРЕДА | B17: 1. | C17: =Звонки!C2 -> 8.00-8.40 | D17: Музыка | E17: Русский язык | F17: ПОУ РУССКИЙ ЯЗЫК | G17: Русский язык
B18: 2. | C18: =Звонки!C3 -> 8.55-9.35 | D18: Математика | E18: Иностранный язык | F18: Естествознание | G18: Иностранный язык
B19: 3. | C19: =Звонки!C4 -> 9.50-10.30 | D19: Иностранный язык | E19: Математика | F19: Русский язык | G19: Литература
B20: 4. | C20: =Звонки!C5 -> 10.50-11.30 | D20: Математика | E20: Литература | F20: Математика | G20: Математика
B21: 5. | C21: =Звонки!C6 -> 11.50-12.30 | D21: Русский язык | E21: Технология | F21: Литература | G21: Естествознание
B22: 6. | C22: =Звонки!C7 -> 12.45-13.25 | D22: Литература | E22: Технология | F22: Математика | G22: Музыка
B23: 7. | C23: =Звонки!C8 -> 13.35-14.15 | E23: ПОУ МАТЕМАТИКА | G23: ПОУ МАТЕМАТИКА
A24: ЧЕТВЕРГ | B24: 1. | C24: =Звонки!C2 -> 8.00-8.40 | D24: Технология | E24: Русский язык | F24: Русский язык | G24: Биология
B25: 2. | C25: =Звонки!C3 -> 8.55-9.35 | D25: Технология | E25: Музыка | F25: Иностранный язык | G25: История
B26: 3. | C26: =Звонки!C4 -> 9.50-10.30 | D26: Русский язык | E26: Иностранный язык | F26: Физическая культура | G26: Математика
B27: 4. | C27: =Звонки!C5 -> 10.50-11.30 | D27: Математика | E27: Математика | F27: История | G27: Иностранный язык
B28: 5. | C28: =Звонки!C6 -> 11.50-12.30 | D28: Литература | E28: Физическая культура | F28: Математика | G28: Русский язык
B29: 6. | C29: =Звонки!C7 -> 12.45-13.25 | D29: Иностранный язык | E29: Литература | F29: Литература | G29: Физическая культура
B30: 7. | C30: =Звонки!C8 -> 13.35-14.15 | D30: ПОУ МАТЕМАТИКА | F30: ПОУ МАТЕМАТИКА
A31: ПЯТНИЦА | B31: 1. | C31: =Звонки!C2 -> 8.00-8.40 | D31: История | E31: Русский язык | F31: Физическая культура | G31: Математика
B32: 2. | C32: =Звонки!C3 -> 8.55-9.35 | D32: ИЗО | E32: История | F32: Математика | G32: Литература
B33: 3. | C33: =Звонки!C4 -> 9.50-10.30 | D33: Физическая культура | E33: ИЗО | F33: История | G33: Русский язык
B34: 4. | C34: =Звонки!C5 -> 10.50-11.30 | D34: Русский язык | E34: Математика | F34: Русский язык | G34: ИЗО
B35: 5. | C35: =Звонки!C6 -> 11.50-12.30 | D35: Математика | E35: Естествознание | F35: ИЗО | G35: Математика
B36: 6. | C36: =Звонки!C7 -> 12.45-13.25 | D36: Иностранный язык | E36: ПОУ РУССКИЙ ЯЗЫК | F36: Музыка | G36: История
B37: 7. | C37: =Звонки!C8 -> 13.35-14.15

Sheet 6 классы
A1: РАСПИСАНИЕ УРОКОВ — 6 КЛАССЫ
A2: Кл. руководитель | D2: Мазырина В.Е. (332) | E2: Пащенко И.Н. (225) | F2: Мазур И.Н. (323) | G2: Зобнин В.А. (222)
A3: День | B3: № | C3: Время | D3: 6 «А» | E3: 6 «Б» | F3: 6 «В» | G3: 6 «Г»
A4: ПОНЕДЕЛЬНИК | B4: 1. | C4: =Звонки!C2 -> 8.00-8.40 | D4: ПОУ МАТЕМАТИКА | E4: Технология | F4: Физическая культура | G4: Русский язык
B5: 2. | C5: =Звонки!C3 -> 8.55-9.35 | D5: Математика | E5: Технология | F5: История | G5: Иностранный язык
B6: 3. | C6: =Звонки!C4 -> 9.50-10.30 | D6: Русский язык | E6: Математика | F6: Математика | G6: История
B7: 4. | C7: =Звонки!C5 -> 10.50-11.30 | D7: История | E7: Русский язык | F7: ИЗО | G7: Математика
B8: 5. | C8: =Звонки!C6 -> 11.50-12.30 | D8: ИЗО | E8: История | F8: Иностранный язык | G8: Русский язык
B9: 6. | C9: =Звонки!C7 -> 12.45-13.25 | D9: Технология | E9: Литература | F9: Русский язык | G9: Физическая культура
B10: 7. | C10: =Звонки!C8 -> 13.35-14.15 | D10: Технология | E10: ПОУ МАТЕМАТИКА
A11: ВТОРНИК | B11: 1. | C11: =Звонки!C2 -> 8.00-8.40 | D11: Русский язык | F11: Технология
B12: 2. | C12: =Звонки!C3 -> 8.55-9.35 | D12: Математика | E12: ИЗО | F12: Технология | G12: История
B13: 3. | C13: =Звонки!C4 -> 9.50-10.30 | D13: Русский язык | E13: География | F13: Русский язык | G13: Математика
B14: 4. | C14: =Звонки!C5 -> 10.50-11.30 | D14: Иностранный язык | E14: Русский язык | F14: Математика | G14: ИЗО
B15: 5. | C15: =Звонки!C6 -> 11.50-12.30 | D15: География | E15: Математика | F15: Биология | G15: Русский язык
B16: 6. | C16: =Звонки!C7 -> 12.45-13.25 | D16: Математика | E16: Музыка | F16: Русский язык | G16: Технология
B17: 7. | C17: =Звонки!C8 -> 13.35-14.15 | D17: ПОУ РУССКИЙ ЯЗЫК | E17: Биология | F17: ПОУ РУССКИЙ ЯЗЫК | G17: Технология
A18: СРЕДА | B18: 1. | C18: =Звонки!C2 -> 8.00-8.40 | D18: История | E18: ПОУ РУССКИЙ ЯЗЫК | G18: География
B19: 2. | C19: =Звонки!C3 -> 8.55-9.35 | D19: Русский язык | E19: Иностранный язык | F19: Физическая культура | G19: Русский язык
B20: 3. | C20: =Звонки!C4 -> 9.50-10.30 | D20: Физическая культура | E20: Математика | F20: География | G20: Литература
B21: 4. | C21: =Звонки!C5 -> 10.50-11.30 | D21: Иностранный язык | E21: Математика | F21: Русский язык | G21: История
B22: 5. | C22: =Звонки!C6 -> 11.50-12.30 | D22: Математика | E22: Русский язык | F22: История | G22: Математика
B23: 6. | C23: =Звонки!C7 -> 12.45-13.25 | D23: Литература | E23: Литература | F23: Математика | G23: Физическая культура
B24: 7. | C24: =Звонки!C8 -> 13.35-14.15 | E24: История | F24: Литература
A25: ЧЕТВЕРГ | B25: 1. | C25: =Звонки!C2 -> 8.00-8.40 | D25: Физическая культура | E25: Русский язык | F25: Русский язык | G25: Математика
B26: 2. | C26: =Звонки!C3 -> 8.55-9.35 | D26: Русский язык | E26: Физическая культура | F26: Математика | G26: Русский язык
B27: 3. | C27: =Звонки!C4 -> 9.50-10.30 | D27: Биология | E27: Русский язык | F27: Иностранный язык | G27: Музыка
B28: 4. | C28: =Звонки!C5 -> 10.50-11.30 | D28: Литература | E28: ПРОЕКТ по ПДД | F28: Литература | G28: Биология
B29: 5. | C29: =Звонки!C6 -> 11.50-12.30 | D29: Музыка | E29: Литература | F29: Математика | G29: Иностранный язык
B30: 6. | C30: =Звонки!C7 -> 12.45-13.25 | D30: ПРОЕКТ по ПДД | E30: Иностранный язык | F30: Музыка | G30: Литература
B31: 7. | C31: =Звонки!C8 -> 13.35-14.15 | F31: ПОУ МАТЕМАТИКА
A32: ПЯТНИЦА | B32: 1. | C32: =Звонки!C2 -> 8.00-8.40 | D32: Русский язык | E32: Иностранный язык | F32: Математика | G32: Русский язык
B33: 2. | C33: =Звонки!C3 -> 8.55-9.35 | D33: Математика | E33: История | F33: Иностранный язык | G33: Литература
B34: 3. | C34: =Звонки!C4 -> 9.50-10.30 | D34: История | E34: Математика | F34: Русский язык | G34: ПРОЕКТ по ПДД
B35: 4. | C35: =Звонки!C5 -> 10.50-11.30 | D35: Литература | E35: Математика | F35: ПРОЕКТ по ПДД | G35: Математика
B36: 5. | C36: =Звонки!C6 -> 11.50-12.30 | D36: Иностранный язык | E36: Русский язык | F36: История | G36: Математика
B37: 6. | C37: =Звонки!C7 -> 12.45-13.25 | D37: Математика | E37: Физическая культура | F37: Литература | G37: Иностранный язык

Sheet 7 классы
A1: РАСПИСАНИЕ УРОКОВ — 7 КЛАССЫ
A2: Кл. руководитель | D2: Логинова И.Я. (244) | E2: Груздева О.П. (342) | F2: Харланова О.В. (223) | G2: Мазур И.Н. (323)
A3: День | B3: № | C3: Время | D3: 7 «А» | E3: 7 «Б» | F3: 7 «В» | G3: 7 «Г»
A4: ПОНЕДЕЛЬНИК | B4: 1. | C4: =Звонки!B2 -> 8.35-9.15 | D4: Русский язык | E4: Физика | F4: Вероятность и статистика | G4: Русский язык
B5: 2. | C5: =Звонки!B3 -> 9.30-10.10 | D5: Алгебра | E5: Музыка | F5: Физика | G5: Физическая культура
B6: 3. | C6: =Звонки!B4 -> 10.25-11.05 | D6: Вероятность и статистика | E6: Русский язык | F6: География | G6: Литература
B7: 4. | C7: =Звонки!B5 -> 11.25-12.05 | D7: Музыка | E7: Вероятность и статистика | F7: Русский язык | G7: География
B8: 5. | C8: =Звонки!B6 -> 12.25-13.05 | D8: Физика | E8: География | F8: Литература | G8: Вероятность и статистика
B9: 6. | C9: =Звонки!B7 -> 13.20-14.00 | D9: Литература | E9: Литература | F9: Физическая культура | G9: Физика
B10: 7. | C10: =Звонки!B8 -> 14.10-14.50 | D10: География | E10: ПОУ МАТЕМАТИКА | F10: Иностранный язык | G10: Иностранный язык
A11: ВТОРНИК | B11: 1. | C11: =Звонки!C2 -> 8.00-8.40 | D11: Информатика | E11: История | F11: Информатика | G11: Русский язык
B12: 2. | C12: =Звонки!C3 -> 8.55-9.35 | D12: История | E12: Информатика | F12: Музыка | G12: Информатика
B13: 3. | C13: =Звонки!C4 -> 9.50-10.30 | D13: Иностранный язык | E13: Иностранный язык | F13: История | G13: Геометрия
B14: 4. | C14: =Звонки!C5 -> 10.50-11.30 | D14: Физическая культура | E14: Биология | F14: Геометрия | G14: Музыка
B15: 5. | C15: =Звонки!C6 -> 11.50-12.30 | D15: Геометрия | E15: Физическая культура | F15: Физическая культура | G15: История
B16: 6. | C16: =Звонки!C7 -> 12.45-13.25 | D16: Русский язык | E16: Алгебра | G16: Иностранный язык
B17: 7. | C17: =Звонки!C8 -> 13.35-14.15 | D17: ПОУ РУССКИЙ ЯЗЫК | E17: Геометрия
A18: СРЕДА | B18: 1. | C18: =Звонки!C2 -> 8.00-8.40 | D18: Русский язык | E18: История | F18: Русский язык | G18: Алгебра
B19: 2. | C19: =Звонки!C3 -> 8.55-9.35 | D19: Литература | E19: Русский язык | F19: Алгебра | G19: Литература
B20: 3. | C20: =Звонки!C4 -> 9.50-10.30 | D20: ИЗО | E20: Технология | F20: Информатика | G20: История
B21: 4. | C21: =Звонки!C5 -> 10.50-11.30 | D21: Иностранный язык | E21: Технология | F21: История | G21: Алгебра
B22: 5. | C22: =Звонки!C6 -> 11.50-12.30 | D22: История | E22: Алгебра | F22: Иностранный язык | G22: ИЗО
B23: 6. | C23: =Звонки!C7 -> 12.45-13.25 | D23: Физическая культура | E23: Русский язык | F23: Литература | G23: Физическая культура
B24: 7. | C24: =Звонки!C8 -> 13.35-14.15 | D24: Алгебра | E24: ПОУ РУССКИЙ ЯЗЫК | F24: ИЗО | G24: ПРОЕКТ «Моя школа»
A25: ЧЕТВЕРГ | B25: 1. | C25: =Звонки!C2 -> 8.00-8.40 | D25: Русский язык | E25: Физика | F25: География | G25: Геометрия
B26: 2. | C26: =Звонки!C3 -> 8.55-9.35 | D26: Биология | E26: Иностранный язык | F26: Физика | G26: География
B27: 3. | C27: =Звонки!C4 -> 9.50-10.30 | D27: География | E27: История | F27: Алгебра | G27: Технология
B28: 4. | C28: =Звонки!C5 -> 10.50-11.30 | D28: История | E28: Литература | F28: Геометрия | G28: Технология
B29: 5. | C29: =Звонки!C6 -> 11.50-12.30 | D29: Геометрия | E29: География | F29: Биология | G29: Русский язык
B30: 6. | C30: =Звонки!C7 -> 12.45-13.25 | D30: Информатика | E30: Геометрия | F30: Русский язык | G30: Физика
B31: 7. | C31: =Звонки!C8 -> 13.35-14.15 | D31: ПОУ МАТЕМАТИКА | F31: ПРОЕКТ «Моя школа» | G31: Иностранный язык
B32: 8.
A33: ПЯТНИЦА | B33: 1. | C33: =Звонки!C2 -> 8.00-8.40 | D33: Физика | E33: Алгебра | F33: ПОУ РУССКИЙ ЯЗЫК | G33: История
B34: 2. | C34: =Звонки!C3 -> 8.55-9.35 | D34: Технология | E34: ИЗО | F34: Русский язык | G34: Алгебра
B35: 3. | C35: =Звонки!C4 -> 9.50-10.30 | D35: Технология | E35: Русский язык | F35: История | G35: Информатика
B36: 4. | C36: =Звонки!C5 -> 10.50-11.30 | D36: Иностранный язык | E36: ПРОЕКТ «Моя школа» | F36: Иностранный язык | G36: Русский язык
B37: 5. | C37: =Звонки!C6 -> 11.50-12.30 | D37: ПРОЕКТ «Моя школа» | E37: Иностранный язык | F37: Алгебра | G37: Биология
B38: 6. | C38: =Звонки!C7 -> 12.45-13.25 | D38: Алгебра | E38: Физическая культура | F38: Технология
B39: 7. | C39: =Звонки!C8 -> 13.35-14.15 | E39: Информатика | F39: Технология

Sheet 8 классы
A1: РАСПИСАНИЕ УРОКОВ — 8 КЛАССЫ
A2: Кл. руководитель | D2: Будылева К.Н. (324) | E2: Свиридова Е.В. (325) | F2: Сибилева И.В. (221) | G2: Бускина З.М. (331)
A3: День | B3: № | C3: Время | D3: 8 «А» | E3: 8 «Б» | F3: 8 «В» | G3: 8 «Г»
A4: ПОНЕДЕЛЬНИК | B4: 1. | C4: =Звонки!B2 -> 8.35-9.15 | D4: Алгебра | E4: Музыка | F4: Иностранный язык | G4: Химия
B5: 2. | C5: =Звонки!B3 -> 9.30-10.10 | D5: Информатика | E5: Алгебра | F5: Химия | G5: Биология
B6: 3. | C6: =Звонки!B4 -> 10.25-11.05 | D6: Биология | E6: Информатика | F6: История | G6: Физика
B7: 4. | C7: =Звонки!B5 -> 11.25-12.05 | D7: Химия | E7: Биология | F7: Информатика | G7: Русский язык
B8: 5. | C8: =Звонки!B6 -> 12.25-13.05 | D8: Русский язык | E8: Химия | F8: Биология | G8: Алгебра
B9: 6. | C9: =Звонки!B7 -> 13.20-14.00 | D9: Алгебра | E9: История | F9: Литература | G9: Информатика
B10: 7. | C10: =Звонки!B8 -> 14.10-14.50 | D10: История | E10: Русский язык | F10: Физика | G10: Физическая культура
A11: ВТОРНИК | B11: 1. | C11: =Звонки!C2 -> 8.00-8.40 | D11: Биология | E11: Иностранный язык | F11: Геометрия | G11: Алгебра
B12: 2. | C12: =Звонки!C3 -> 8.55-9.35 | D12: Физика | E12: Русский язык | F12: Обществознание | G12: Русский язык
B13: 3. | C13: =Звонки!C4 -> 9.50-10.30 | D13: Физическая культура | E13: Алгебра | F13: Музыка | G13: История
B14: 4. | C14: =Звонки!C5 -> 10.50-11.30 | D14: Русский язык | E14: Литература | F14: Физическая культура | G14: Биология
B15: 5. | C15: =Звонки!C6 -> 11.50-12.30 | D15: Геометрия | E15: Физика | F15: Алгебра | G15: Иностранный язык
B16: 6. | C16: =Звонки!C7 -> 12.45-13.25 | D16: Иностранный язык | E16: Геометрия | F16: Русский язык | G16: Литература
B17: 7. | C17: =Звонки!C8 -> 13.35-14.15 | D17: Обществознание | E17: Физическая культура | F17: Иностранный язык | G17: Геометрия
A18: СРЕДА | B18: 1. | C18: =Звонки!C2 -> 8.00-8.40 | D18: Технология | E18: Вероятность и статистика | F18: ПОУ РУССКИЙ ЯЗЫК | G18: Химия
B19: 2. | C19: =Звонки!C3 -> 8.55-9.35 | D19: Химия | E19: География | F19: Технология | G19: Русский язык
B20: 3. | C20: =Звонки!C4 -> 9.50-10.30 | D20: Литература | E20: ОБЗР | F20: Химия | G20: Иностранный язык
B21: 4. | C21: =Звонки!C5 -> 10.50-11.30 | D21: География | E21: Химия | F21: Русский язык | G21: Музыка
B22: 5. | C22: =Звонки!C6 -> 11.50-12.30 | D22: Музыка | E22: Русский язык | F22: Вероятность и статистика | G22: Вероятность и статистика
B23: 6. | C23: =Звонки!C7 -> 12.45-13.25 | D23: Вероятность и статистика | E23: Иностранный язык | F23: Алгебра | G23: География
B24: 7. | C24: =Звонки!C8 -> 13.35-14.15 | D24: ПОУ МАТЕМАТИКА | F24: География | G24: Физическая культура
A25: ЧЕТВЕРГ | B25: 1. | C25: =Звонки!C2 -> 8.00-8.40 | D25: Геометрия | E25: Обществознание | F25: Русский язык | G25: Иностранный язык
B26: 2. | C26: =Звонки!C3 -> 8.55-9.35 | D26: Русский язык | E26: Иностранный язык | F26: Информатика | G26: Геометрия
B27: 3. | C27: =Звонки!C4 -> 9.50-10.30 | D27: ОБЗР | E27: Литература | F27: Литература | G27: Обществознание
B28: 4. | C28: =Звонки!C5 -> 10.50-11.30 | D28: Физическая культура | E28: Физика | F28: Геометрия | G28: Русский язык
B29: 5. | C29: =Звонки!C6 -> 11.50-12.30 | D29: Иностранный язык | E29: Геометрия | F29: История | G29: Физика
B30: 6. | C30: =Звонки!C7 -> 12.45-13.25 | D30: История | E30: Технология | F30: ОБЗР | G30: Технология
B31: 7. | C31: =Звонки!C8 -> 13.35-14.15 | D31: Физика | F31: ПОУ МАТЕМАТИКА
A32: ПЯТНИЦА | B32: 1. | C32: =Звонки!C2 -> 8.00-8.40 | D32: Информатика | E32: Алгебра | F32: Биология
B33: 2. | C33: =Звонки!C3 -> 8.55-9.35 | D33: Русский язык | E33: Биология | F33: География | G33: ОБЗР
B34: 3. | C34: =Звонки!C4 -> 9.50-10.30 | D34: Литература | E34: География | F34: Иностранный язык | G34: Алгебра
B35: 4. | C35: =Звонки!C5 -> 10.50-11.30 | D35: Алгебра | E35: История | F35: Физическая культура | G35: Информатика
B36: 5. | C36: =Звонки!C6 -> 11.50-12.30 | D36: География | E36: Русский язык | F36: Алгебра | G36: Литература
B37: 6. | C37: =Звонки!C7 -> 12.45-13.25 | D37: Иностранный язык | E37: Информатика | F37: Русский язык | G37: География
B38: 7. | C38: =Звонки!C8 -> 13.35-14.15 | D38: ПОУ РУССКИЙ ЯЗЫК | E38: Физическая культура | F38: Физика | G38: История

Sheet 9 классы
A1: РАСПИСАНИЕ УРОКОВ — 9 КЛАССЫ
A2: Кл. руководитель | D2: Емельянова Н.В. (226) | E2: Маланова С.В. (246) | F2: Чекалина Т.А. (322) | G2: Груздева О.П. (342)
A3: День | B3: № | C3: Время | D3: 9 «А» | E3: 9 «Б» | F3: 9 «В» | G3: 9 «Г»
A4: ПОНЕДЕЛЬНИК | B4: 1. | C4: =Звонки!B2 -> 8.35-9.15 | D4: Литература | E4: Технология | F4: Русский язык | G4: Биология
B5: 2. | C5: =Звонки!B3 -> 9.30-10.10 | D5: Русский язык | E5: Алгебра | F5: Литература | G5: Литература
B6: 3. | C6: =Звонки!B4 -> 10.25-11.05 | D6: Иностранный язык | E6: Химия | F6: Технология | G6: Алгебра
B7: 4. | C7: =Звонки!B5 -> 11.25-12.05 | D7: Алгебра | E7: Русский язык | F7: Иностранный язык | G7: Вероятность и статистика
B8: 5. | C8: =Звонки!B6 -> 12.25-13.05 | D8: ОБЗР | E8: Литература | F8: Алгебра | G8: Иностранный язык
B9: 6. | C9: =Звонки!B7 -> 13.20-14.00 | D9: История | E9: Иностранный язык | F9: Алгебра
B10: 7. | C10: =Звонки!B8 -> 14.10-14.50 | D10: Биология | E10: Вероятность и статистика | F10: Физическая культура
B11: 8. | C11: =Звонки!B9 -> 14.55-15.35 | E11: ОГЭ (МАТЕМАТИКА)
A12: ВТОРНИК | B12: 1. | C12: =Звонки!C2 -> 8.00-8.40 | D12: Физическая культура | E12: География | F12: Химия | G12: Физика
B13: 2. | C13: =Звонки!C3 -> 8.55-9.35 | D13: География | E13: Биология | F13: Физическая культура | G13: Иностранный язык
B14: 3. | C14: =Звонки!C4 -> 9.50-10.30 | D14: Алгебра | E14: Геометрия | F14: Физика | G14: Обществознание
B15: 4. | C15: =Звонки!C5 -> 10.50-11.30 | D15: Физика | E15: Обществознание | F15: Алгебра | G15: Геометрия
B16: 5. | C16: =Звонки!C6 -> 11.50-12.30 | D16: Технология | E16: Химия | F16: Обществознание | G16: Русский язык
B17: 6. | C17: =Звонки!C7 -> 12.45-13.25 | D17: Обществознание | E17: Физика | F17: Биология | G17: Физическая культура
B18: 7. | C18: =Звонки!C8 -> 13.35-14.15 | D18: Алгебра | E18: Физическая культура | F18: География | G18: Химия
B19: 8. | C19: =Звонки!C9 -> 14.20-15.00 | D19: ОГЭ (МАТЕМАТИКА) | F19: ПОУ ИНФОРМАТИКА | G19: ОГЭ (МАТЕМАТИКА)
B20: 9. | C20: =Звонки!C10 -> 15.05-15.45 | D20: ОГЭ (МАТЕМАТИКА)
A21: СРЕДА | B21: 1. | C21: =Звонки!C2 -> 8.00-8.40 | D21: Геометрия | E21: Алгебра | F21: Физика | G21: Информатика
B22: 2. | C22: =Звонки!C3 -> 8.55-9.35 | D22: Геометрия | E22: История | F22: Иностранный язык | G22: Физика
B23: 3. | C23: =Звонки!C4 -> 9.50-10.30 | D23: Физика | E23: Русский язык | F23: История | G23: Литература
B24: 4. | C24: =Звонки!C5 -> 10.50-11.30 | D24: Иностранный язык | E24: Физика | F24: Литература | G24: Алгебра
B25: 5. | C25: =Звонки!C6 -> 11.50-12.30 | D25: Химия | E25: Информатика | F25: Русский язык | G25: Иностранный язык
B26: 6. | C26: =Звонки!C7 -> 12.45-13.25 | D26: Информатика | E26: ОБЗР | F26: Геометрия | G26: История
B27: 7. | C27: =Звонки!C8 -> 13.35-14.15 | D27: ПОУ ИНФОРМАТИКА | E27: Иностранный язык | F27: Геометрия | G27: Химия
B28: 8. | C28: =Звонки!C9 -> 14.20-15.00 | E28: ПОУ ОБЩЕСТВО | F28: ОГЭ (МАТЕМАТИКА) | G28: ПОУ ОБЩЕСТВО
A29: ЧЕТВЕРГ | B29: 1. | C29: =Звонки!C2 -> 8.00-8.40 | D29: Физическая культура | E29: ОГЭ (РУССКИЙ) | F29: ОБЗР | G29: История
B30: 2. | C30: =Звонки!C3 -> 8.55-9.35 | D30: История | E30: ОГЭ (РУССКИЙ) | F30: Информатика | G30: Русский язык
B31: 3. | C31: =Звонки!C4 -> 9.50-10.30 | D31: Физика | E31: Литература | F31: Иностранный язык | G31: Геометрия
B32: 4. | C32: =Звонки!C5 -> 10.50-11.30 | D32: Иностранный язык | E32: Иностранный язык | F32: История | G32: География
B33: 5. | C33: =Звонки!C6 -> 11.50-12.30 | D33: Литература | E33: Геометрия | F33: Русский язык | G33: Технология
B34: 6. | C34: =Звонки!C7 -> 12.45-13.25 | D34: Русский язык | E34: История | F34: ОГЭ (РУССКИЙ) | G34: Физическая культура
B35: 7. | C35: =Звонки!C8 -> 13.35-14.15 | D35: ОГЭ (РУССКИЙ) | E35: География | F35: ОГЭ (РУССКИЙ) | G35: Литература
B36: 8. | C36: =Звонки!C9 -> 14.20-15.00 | D36: ОГЭ (РУССКИЙ) | E36: Физическая культура | F36: ПОУ ОБЩЕСТВО | G36: ОГЭ (РУССКИЙ)
B37: 9. | C37: =Звонки!C10 -> 15.05-15.45 | G37: ОГЭ (РУССКИЙ)
A38: ПЯТНИЦА | B38: 1. | C38: =Звонки!C2 -> 8.00-8.40 | D38: Вероятность и статистика | E38: ОГЭ (МАТЕМАТИКА) | F38: История | G38: География
B39: 2. | C39: =Звонки!C3 -> 8.55-9.35 | D39: Химия | E39: Алгебра | F39: Литература | G39: Физика
B40: 3. | C40: =Звонки!C4 -> 9.50-10.30 | D40: Русский язык | E40: Физика | F40: Биология | G40: ОБЗР ОГЭ (МАТЕМАТИКА)
...

Sheet 10-11 классы
A1: РАСПИСАНИЕ УРОКОВ — 10-11 КЛАССЫ
A2: Кл. руководитель | D2: Краснова Н.В. (243) | F2: Илюшина Н.Н. (334)
A3: День | B3: № | C3: Время | D3: 10«А» СОЦ-ЭК | E3: 10«А» ТЕХНОЛ | F3: 11«А» СОЦ-ЭК | G3: 11«А» ТЕХНОЛ
A4: ПОНЕДЕЛЬНИК | B4: 1. | C4: =Звонки!B2 -> 8.35-9.15 | D4: Иностранный язык | E4: Иностранный язык
B5: 2. | C5: =Звонки!B3 -> 9.30-10.10 | D5: География | E5: География | F5: Русский язык | G5: Русский язык
B6: 3. | C6: =Звонки!B4 -> 10.25-11.05 | D6: Алгебра | E6: Алгебра | F6: Литература | G6: Литература
B7: 4. | C7: =Звонки!B5 -> 11.25-12.05 | D7: Русский язык | E7: Русский язык | F7: Физика | G7: Физика
B8: 5. | C8: =Звонки!B6 -> 12.25-13.05 | D8: Литература | E8: Литература | F8: Алгебра | G8: Алгебра
B9: 6. | C9: =Звонки!B7 -> 13.20-14.00 | D9: Алгебра | E9: Алгебра | F9: Алгебра | G9: Алгебра
B10: 7. | C10: =Звонки!B8 -> 14.10-14.50 | D10: Химия | E10: Химия | F10: Обществознание | G10: Информатика
B11: 8. | C11: =Звонки!B9 -> 14.55-15.35 | F11: История | G11: Информатика
A12: ВТОРНИК | B12: 1. | C12: =Звонки!C2 -> 8.00-8.40 | D12: Русский язык | E12: Русский язык | F12: История | G12: Обществознание
B13: 2. | C13: =Звонки!C3 -> 8.55-9.35 | D13: Геометрия | E13: Геометрия | F13: Геометрия | G13: Геометрия
B14: 3. | C14: =Звонки!C4 -> 9.50-10.30 | D14: Биология | E14: Биология | F14: ОБЗР | G14: ОБЗР
B15: 4. | C15: =Звонки!C5 -> 10.50-11.30 | D15: Информатика | E15: История | F15: Литература | G15: Литература
B16: 5. | C16: =Звонки!C6 -> 11.50-12.30 | D16: Физическая культура | E16: Физическая культура | F16: ЭЛЕКТИВ ИНФОРМ | G16: ЭЛЕКТИВ ЧЕРЧЕНИЕ
B17: 6. | C17: =Звонки!C7 -> 12.45-13.25 | D17: История | E17: Информатика | F17: Обществознание | G17: История
B18: 7. | C18: =Звонки!C8 -> 13.35-14.15 | D18: Обществознание | E18: Физика | F18: Геометрия | G18: Геометрия
B19: 8. | C19: =Звонки!C9 -> 14.20-15.00 | D19: ПОУ МАТЕМАТИКА | F19: Обществознание
A20: СРЕДА | B20: 1. | C20: =Звонки!C2 -> 8.00-8.40 | D20: ОБЗР | E20: ОБЗР | F20: Иностранный язык | G20: Иностранный язык
B21: 2. | C21: =Звонки!C3 -> 8.55-9.35 | D21: История | E21: Информатика | F21: Алгебра | G21: Алгебра
B22: 3. | C22: =Звонки!C4 -> 9.50-10.30 | D22: Вероятность и статистика | E22: Вероятность и статистика | F22: Русский язык | G22: Русский язык
B23: 4. | C23: =Звонки!C5 -> 10.50-11.30 | D23: Иностранный язык | E23: Иностранный язык | F23: Литература | G23: Литература
B24: 5. | C24: =Звонки!C6 -> 11.50-12.30 | D24: Литература | E24: Литература | F24: Физика | G24: Физика
B25: 6. | C25: =Звонки!C7 -> 12.45-13.25 | D25: Физика | E25: Обществознание | F25: ЕГЭ (РУССКИЙ) | G25: ЕГЭ (РУССКИЙ)
B26: 7. | C26: =Звонки!C8 -> 13.35-14.15 | D26: Обществознание | E26: Физика | F26: Геометрия | G26: Геометрия
B27: 8. | C27: =Звонки!C9 -> 14.20-15.00 | F27: ПОУ МАТЕМАТИКА | G27: ПОУ МАТЕМАТИКА
A28: ЧЕТВЕРГ | B28: 1. | C28: =Звонки!C2 -> 8.00-8.40 | D28: История | E28: Информатика | F28: ЕГЭ (МАТЕМАТИКА) | G28: ЕГЭ (МАТЕМАТИКА)
B29: 2. | C29: =Звонки!C3 -> 8.55-9.35 | D29: ИП | E29: ИП | F29: Геометрия | G29: Геометрия
B30: 3. | C30: =Звонки!C4 -> 9.50-10.30 | D30: Алгебра | E30: Алгебра | F30: История | G30: Информатика
B31: 4. | C31: =Звонки!C5 -> 10.50-11.30 | D31: ПОУ РУССКИЙ ЯЗЫК | E31: ПОУ РУССКИЙ ЯЗЫК | F31: История | G31: Информатика
B32: 5. | C32: =Звонки!C6 -> 11.50-12.30 | D32: История | E32: Информатика | F32: ПОУ РУССКИЙ ЯЗЫК | G32: ПОУ РУССКИЙ ЯЗЫК
B33: 6. | C33: =Звонки!C7 -> 12.45-13.25 | D33: Алгебра | E33: Алгебра | F33: Вероятность и статистика | G33: Вероятность и статистика
B34: 7. | C34: =Звонки!C8 -> 13.35-14.15 | D34: ПОУ ИНФОРМАТИКА | E34: История | F34: Обществознание | G34: История
A35: ПЯТНИЦА | B35: 1. | C35: =Звонки!C2 -> 8.00-8.40 | D35: Иностранный язык | E35: Иностранный язык | F35: Химия | G35: Химия
B36: 2. | C36: =Звонки!C3 -> 8.55-9.35 | D36: ЭЛЕКТИВ ИНФОРМ | E36: Обществознание | F36: Физическая культура | G36: Физическая культура
B37: 3. | C37: =Звонки!C4 -> 9.50-10.30 | D37: Литература | E37: Литература | F37: Иностранный язык | G37: Иностранный язык
B38: 4. | C38: =Звонки!C5 -> 10.50-11.30 | D38: Обществознание | E38: Физика | F38: Биология | G38: Биология
B39: 5. | C39: =Звонки!C6 -> 11.50-12.30 | D39: Обществознание | E39: Физика | F39: Информатика | G39: Обществознание
B40: 6. | C40: =Звонки!C7 -> 12.45-13.25 | D40: Геометрия | E40: Геометрия | F40: Алгебра | G40: Алгебра
...

Sheet Предметы
A1: Предмет | B1: Цвет | D1: Палитра цветов
A2: Алгебра | D2: 1 | E2: Голубой
A3: Биология | D3: 2 | E3: Зелёный
A4: Вероятность и статистика | D4: 3 | E4: Жёлтый
A5: География | D5: 4 | E5: Оранжевый
A6: Геометрия | D6: 5 | E6: Розовый
A7: ЕГЭ (МАТЕМАТИКА) | D7: 6 | E7: Фиолетовый
A8: ЕГЭ (РУССКИЙ) | D8: 7 | E8: Красный
A9: Естествознание | D9: 8 | E9: Серый
A10: ИЗО | D10: 9 | E10: Бирюзовый
A11: Иностранный язык | D11: 10 | E11: Бежевый
A12: Информатика
A13: ИП
A14: История
A15: Литература
A16: Математика
A17: Музыка
A18: ОБЗР
A19: ОБЗР ОГЭ (МАТЕМАТИКА)
A20: Обществознание
A21: ОГЭ (МАТЕМАТИКА)
A22: ОГЭ (РУССКИЙ)
A23: ПОУ ИНОСТРАННЫЙ
... A36: ЭЛЕКТИВ ЧЕРЧЕНИЕ

Sheet Звонки
A1: Урок № | B1: Понедельник | C1: Вт–Сб
A2: 1. | B2: 8.35-9.15 | C2: 8.00-8.40
A3: 2. | B3: 9.30-10.10 | C3: 8.55-9.35
A4: 3. | B4: 10.25-11.05 | C4: 9.50-10.30
A5: 4. | B5: 11.25-12.05 | C5: 10.50-11.30
A6: 5. | B6: 12.25-13.05 | C6: 11.50-12.30
A7: 6. | B7: 13.20-14.00 | C7: 12.45-13.25
A8: 7. | B8: 14.10-14.50 | C8: 13.35-14.15
A9: 8. | B9: 14.55-15.35 | C9: 14.20-15.00
A10: 9. | C10: 15.05-15.45
